Workbook

Sheet Eredmények
A1: Paraméter | B1: Érték | C1: Indoklás | F1: Járadéktag | G1: Nyugdíj előtti záró egyenleg | H1: Éves induló nyugdíj | I1: Havi induló nyugdíj
A2: Munkába állás kora (év) | B2: 24 | C2: diploma megszerzés éve, munkakezdés éve | F2: =SUM('Tábla 2020'!H64:H109) -> 9.6419954 | G2: ='Havi számolás'!M1 -> 2.044948e+08 | H2: =G2/F2 -> 21208764 | I2: =H2/12 -> 1767397
A3: Nyugdíjkorhatár (év) | B3: 67 | C3: Várható nyugdíjkorhatár, demográfiai kürölményeknek köszönhetően
A4: Junior éves bér (életkor 24-27) | B4: =12*820000 -> 9840000 | C4: Nyilvános béradatok alapján választott mediánközeli bruttó bér
A5: Medior éves bér (életkor 28-32) | B5: ='Havi számolás'!D49*12*1.15 -> 12365299 | C5: 15%-os egyszeri karrierszintváltási béremelés utáni bruttó bér
A6: Senior éves bér (életkor 33-64) | B6: ='Havi számolás'!D109*12*1.2 -> 16700703 | C6: 20%-os egyszeri karrierszintváltási béremelés utáni bruttó bér
A7: Éves bérnövekedés | B7: 0.03 | C7: Konzervatív, 3%-os középtávú inflációs célhoz közeli érték
A8: Járulékkulcs | B8: 0.08 | C8: Modellparaméterként választott, saját célú nyugdíjmegtakarítási ráta
A9: Éves hozam | B9: 0.045 | C9: Konzervatív nominális hozam, a hosszú állampapírhozamok alatt
A10: Halandóság | B10: Férfi | C10: 2020-as magyar férfi halandósági tábla alapján

Sheet Havi számolás
A1: Év | B1: Életkor | C1: Hónap | D1: Bér | E1: Nyitó Egyenleg | F1: Befizetés | G1: Hozam | H1: Záró Egyenleg | L1: Nyugdíj előtti záró egyenleg | M1: {=LOOKUP(2,1/(H:H<>""),H:H)} -> 2.044948e+08
A2: =INT((ROW(A1)-1)/12+2028) -> 2028 | B2: =INT((A2-2004)+(C2-1)/12) -> 24 | C2: 1 | D2: =Eredmények!$B$4/12*(1+Eredmények!$B$7)^('Havi számolás'!B2-24) -> 820000 | E2: 0 | F2: =Eredmények!$B$8*D2 -> 65600 | G2: =SUM(E2:F2)*((1+Eredmények!$B$9)^(1/12)-1) -> 241.0675 | H2: =E2+F2+G2 -> 65841.067
A3: =INT((ROW(A2)-1)/12+2028) -> 2028 | B3: =INT((A3-2004)+(C3-1)/12) -> 24 | C3: 2 | D3: =Eredmények!$B$4/12*(1+Eredmények!$B$7)^('Havi számolás'!B3-24) -> 820000 | E3: =H2 -> 65841.067 | F3: =Eredmények!$B$8*D3 -> 65600 | G3: =SUM(E3:F3)*((1+Eredmények!$B$9)^(1/12)-1) -> 483.02087 | H3: =E3+F3+G3 -> 131924.09
A4: =INT((ROW(A3)-1)/12+2028) -> 2028 | B4: =INT((A4-2004)+(C4-1)/12) -> 24 | C4: 3 | D4: =Eredmények!$B$4/12*(1+Eredmények!$B$7)^('Havi számolás'!B4-24) -> 820000 | E4: =H3 -> 131924.09 | F4: =Eredmények!$B$8*D4 -> 65600 | G4: =SUM(E4:F4)*((1+Eredmények!$B$9)^(1/12)-1) -> 725.86338 | H4: =E4+F4+G4 -> 198249.95
A5: =INT((ROW(A4)-1)/12+2028) -> 2028 | B5: =INT((A5-2004)+(C5-1)/12) -> 24 | C5: 4 | D5: =Eredmények!$B$4/12*(1+Eredmények!$B$7)^('Havi számolás'!B5-24) -> 820000 | E5: =H4 -> 198249.95 | F5: =Eredmények!$B$8*D5 -> 65600 | G5: =SUM(E5:F5)*((1+Eredmények!$B$9)^(1/12)-1) -> 969.59828 | H5: =E5+F5+G5 -> 264819.55
A6: =INT((ROW(A5)-1)/12+2028) -> 2028 | B6: =INT((A6-2004)+(C6-1)/12) -> 24 | C6: 5 | D6: =Eredmények!$B$4/12*(1+Eredmények!$B$7)^('Havi számolás'!B6-24) -> 820000 | E6: =H5 -> 264819.55 | F6: =Eredmények!$B$8*D6 -> 65600 | G6: =SUM(E6:F6)*((1+Eredmények!$B$9)^(1/12)-1) -> 1214.2289 | H6: =E6+F6+G6 -> 331633.78
A7: =INT((ROW(A6)-1)/12+2028) -> 2028 | B7: =INT((A7-2004)+(C7-1)/12) -> 24 | C7: 6 | D7: =Eredmények!$B$4/12*(1+Eredmények!$B$7)^('Havi számolás'!B7-24) -> 820000 | E7: =H6 -> 331633.78 | F7: =Eredmények!$B$8*D7 -> 65600 | G7: =SUM(E7:F7)*((1+Eredmények!$B$9)^(1/12)-1) -> 1459.7584 | H7: =E7+F7+G7 -> 398693.54
A8: =INT((ROW(A7)-1)/12+2028) -> 2028 | B8: =INT((A8-2004)+(C8-1)/12) -> 24 | C8: 7 | D8: =Eredmények!$B$4/12*(1+Eredmények!$B$7)^('Havi számolás'!B8-24) -> 820000 | E8: =H7 -> 398693.54 | F8: =Eredmények!$B$8*D8 -> 65600 | G8: =SUM(E8:F8)*((1+Eredmények!$B$9)^(1/12)-1) -> 1706.1903 | H8: =E8+F8+G8 -> 465999.73
A9: =INT((ROW(A8)-1)/12+2028) -> 2028 | B9: =INT((A9-2004)+(C9-1)/12) -> 24 | C9: 8 | D9: =Eredmények!$B$4/12*(1+Eredmények!$B$7)^('Havi számolás'!B9-24) -> 820000 | E9: =H8 -> 465999.73 | F9: =Eredmények!$B$8*D9 -> 65600 | G9: =SUM(E9:F9)*((1+Eredmények!$B$9)^(1/12)-1) -> 1953.5277 | H9: =E9+F9+G9 -> 533553.26
A10: =INT((ROW(A9)-1)/12+2028) -> 2028 | B10: =INT((A10-2004)+(C10-1)/12) -> 24 | C10: 9 | D10: =Eredmények!$B$4/12*(1+Eredmények!$B$7)^('Havi számolás'!B10-24) -> 820000 | E10: =H9 -> 533553.26 | F10: =Eredmények!$B$8*D10 -> 65600 | G10: =SUM(E10:F10)*((1+Eredmények!$B$9)^(1/12)-1) -> 2201.774 | H10: =E10+F10+G10 -> 601355.03
A11: =INT((ROW(A10)-1)/12+2028) -> 2028 | B11: =INT((A11-2004)+(C11-1)/12) -> 24 | C11: 10 | D11: =Eredmények!$B$4/12*(1+Eredmények!$B$7)^('Havi számolás'!B11-24) -> 820000 | E11: =H10 -> 601355.03 | F11: =Eredmények!$B$8*D11 -> 65600 | G11: =SUM(E11:F11)*((1+Eredmények!$B$9)^(1/12)-1) -> 2450.9326 | H11: =E11+F11+G11 -> 669405.96
A12: =INT((ROW(A11)-1)/12+2028) -> 2028 | B12: =INT((A12-2004)+(C12-1)/12) -> 24 | C12: 11 | D12: =Eredmények!$B$4/12*(1+Eredmények!$B$7)^('Havi számolás'!B12-24) -> 820000 | E12: =H11 -> 669405.96 | F12: =Eredmények!$B$8*D12 -> 65600 | G12: =SUM(E12:F12)*((1+Eredmények!$B$9)^(1/12)-1) -> 2701.0068 | H12: =E12+F12+G12 -> 737706.97
A13: =INT((ROW(A12)-1)/12+2028) -> 2028 | B13: =INT((A13-2004)+(C13-1)/12) -> 24 | C13: 12 | D13: =Eredmények!$B$4/12*(1+Eredmények!$B$7)^('Havi számolás'!B13-24) -> 820000 | E13: =H12 -> 737706.97 | F13: =Eredmények!$B$8*D13 -> 65600 | G13: =SUM(E13:F13)*((1+Eredmények!$B$9)^(1/12)-1) -> 2952 | H13: =E13+F13+G13 -> 806258.97
A14: =INT((ROW(A13)-1)/12+2028) -> 2029 | B14: =INT((A14-2004)+(C14-1)/12) -> 25 | C14: =C2 -> 1 | D14: =Eredmények!$B$4/12*(1+Eredmények!$B$7)^('Havi számolás'!B14-24) -> 844600 | E14: =H13 -> 806258.97 | F14: =Eredmények!$B$8*D14 -> 67568 | G14: =SUM(E14:F14)*((1+Eredmények!$B$9)^(1/12)-1) -> 3211.1476 | H14: =E14+F14+G14 -> 877038.12
A15: =INT((ROW(A14)-1)/12+2028) -> 2029 | B15: =INT((A15-2004)+(C15-1)/12) -> 25 | C15: =C3 -> 2 | D15: =Eredmények!$B$4/12*(1+Eredmények!$B$7)^('Havi számolás'!B15-24) -> 844600 | E15: =H14 -> 877038.12 | F15: =Eredmények!$B$8*D15 -> 67568 | G15: =SUM(E15:F15)*((1+Eredmények!$B$9)^(1/12)-1) -> 3471.2474 | H15: =E15+F15+G15 -> 948077.36
A16: =INT((ROW(A15)-1)/12+2028) -> 2029 | B16: =INT((A16-2004)+(C16-1)/12) -> 25 | C16: =C4 -> 3 | D16: =Eredmények!$B$4/12*(1+Eredmények!$B$7)^('Havi számolás'!B16-24) -> 844600 | E16: =H15 -> 948077.36 | F16: =Eredmények!$B$8*D16 -> 67568 | G16: =SUM(E16:F16)*((1+Eredmények!$B$9)^(1/12)-1) -> 3732.3031 | H16: =E16+F16+G16 -> 1019377.7
A17: =INT((ROW(A16)-1)/12+2028) -> 2029 | B17: =INT((A17-2004)+(C17-1)/12) -> 25 | C17: =C5 -> 4 | D17: =Eredmények!$B$4/12*(1+Eredmények!$B$7)^('Havi számolás'!B17-24) -> 844600 | E17: =H16 -> 1019377.7 | F17: =Eredmények!$B$8*D17 -> 67568 | G17: =SUM(E17:F17)*((1+Eredmények!$B$9)^(1/12)-1) -> 3994.3182 | H17: =E17+F17+G17 -> 1090940
A18: =INT((ROW(A17)-1)/12+2028) -> 2029 | B18: =INT((A18-2004)+(C18-1)/12) -> 25 | C18: =C6 -> 5 | D18: =Eredmények!$B$4/12*(1+Eredmények!$B$7)^('Havi számolás'!B18-24) -> 844600 | E18: =H17 -> 1090940 | F18: =Eredmények!$B$8*D18 -> 67568 | G18: =SUM(E18:F18)*((1+Eredmények!$B$9)^(1/12)-1) -> 4257.296 | H18: =E18+F18+G18 -> 1162765.3
A19: =INT((ROW(A18)-1)/12+2028) -> 2029 | B19: =INT((A19-2004)+(C19-1)/12) -> 25 | C19: =C7 -> 6 | D19: =Eredmények!$B$4/12*(1+Eredmények!$B$7)^('Havi számolás'!B19-24) -> 844600 | E19: =H18 -> 1162765.3 | F19: =Eredmények!$B$8*D19 -> 67568 | G19: =SUM(E19:F19)*((1+Eredmények!$B$9)^(1/12)-1) -> 4521.2403 | H19: =E19+F19+G19 -> 1234854.5
A20: =INT((ROW(A19)-1)/12+2028) -> 2029 | B20: =INT((A20-2004)+(C20-1)/12) -> 25 | C20: =C8 -> 7 | D20: =Eredmények!$B$4/12*(1+Eredmények!$B$7)^('Havi számolás'!B20-24) -> 844600 | E20: =H19 -> 1234854.5 | F20: =Eredmények!$B$8*D20 -> 67568 | G20: =SUM(E20:F20)*((1+Eredmények!$B$9)^(1/12)-1) -> 4786.1545 | H20: =E20+F20+G20 -> 1307208.7
A21: =INT((ROW(A20)-1)/12+2028) -> 2029 | B21: =INT((A21-2004)+(C21-1)/12) -> 25 | C21: =C9 -> 8 | D21: =Eredmények!$B$4/12*(1+Eredmények!$B$7)^('Havi számolás'!B21-24) -> 844600 | E21: =H20 -> 1307208.7 | F21: =Eredmények!$B$8*D21 -> 67568 | G21: =SUM(E21:F21)*((1+Eredmények!$B$9)^(1/12)-1) -> 5052.0423 | H21: =E21+F21+G21 -> 1379828.7
A22: =INT((ROW(A21)-1)/12+2028) -> 2029 | B22: =INT((A22-2004)+(C22-1)/12) -> 25 | C22: =C10 -> 9 | D22: =Eredmények!$B$4/12*(1+Eredmények!$B$7)^('Havi számolás'!B22-24) -> 844600 | E22: =H21 -> 1379828.7 | F22: =Eredmények!$B$8*D22 -> 67568 | G22: =SUM(E22:F22)*((1+Eredmények!$B$9)^(1/12)-1) -> 5318.9071 | H22: =E22+F22+G22 -> 1452715.6
A23: =INT((ROW(A22)-1)/12+2028) -> 2029 | B23: =INT((A23-2004)+(C23-1)/12) -> 25 | C23: =C11 -> 10 | D23: =Eredmények!$B$4/12*(1+Eredmények!$B$7)^('Havi számolás'!B23-24) -> 844600 | E23: =H22 -> 1452715.6 | F23: =Eredmények!$B$8*D23 -> 67568 | G23: =SUM(E23:F23)*((1+Eredmények!$B$9)^(1/12)-1) -> 5586.7526 | H23: =E23+F23+G23 -> 1525870.4
A24: =INT((ROW(A23)-1)/12+2028) -> 2029 | B24: =INT((A24-2004)+(C24-1)/12) -> 25 | C24: =C12 -> 11 | D24: =Eredmények!$B$4/12*(1+Eredmények!$B$7)^('Havi számolás'!B24-24) -> 844600 | E24: =H23 -> 1525870.4 | F24: =Eredmények!$B$8*D24 -> 67568 | G24: =SUM(E24:F24)*((1+Eredmények!$B$9)^(1/12)-1) -> 5855.5823 | H24: =E24+F24+G24 -> 1599294
A25: =INT((ROW(A24)-1)/12+2028) -> 2029 | B25: =INT((A25-2004)+(C25-1)/12) -> 25 | C25: =C13 -> 12 | D25: =Eredmények!$B$4/12*(1+Eredmények!$B$7)^('Havi számolás'!B25-24) -> 844600 | E25: =H24 -> 1599294 | F25: =Eredmények!$B$8*D25 -> 67568 | G25: =SUM(E25:F25)*((1+Eredmények!$B$9)^(1/12)-1) -> 6125.4 | H25: =E25+F25+G25 -> 1672987.4
... A49: =INT((ROW(A48)-1)/12+2028) -> 2031 | B49: =INT((A49-2004)+(C49-1)/12) -> 27 | C49: =C37 -> 12 | D49: =Eredmények!$B$4/12*(1+Eredmények!$B$7)^('Havi számolás'!B49-24) -> 896036.14 | E49: =H48 -> 3516945.9 | F49: =Eredmények!$B$8*D49 -> 71682.891 | G49: =SUM(E49:F49)*((1+Eredmények!$B$9)^(1/12)-1) -> 13187.527 | H49: =E49+F49+G49 -> 3601816.3
A50: =INT((ROW(A49)-1)/12+2028) -> 2032 | B50: =INT((A50-2004)+(C50-1)/12) -> 28 | C50: =C38 -> 1 | D50: =Eredmények!$B$5/12*(1+Eredmények!$B$7)^('Havi számolás'!B50-28) -> 1030441.6 | E50: =H49 -> 3601816.3 | F50: =Eredmények!$B$8*D50 -> 82435.325 | G50: =SUM(E50:F50)*((1+Eredmények!$B$9)^(1/12)-1) -> 13538.923 | H50: =E50+F50+G50 -> 3697790.6 | J50: Medior béremelkedés: 15%
A51: =INT((ROW(A50)-1)/12+2028) -> 2032 | B51: =INT((A51-2004)+(C51-1)/12) -> 28 | C51: =C39 -> 2 | D51: =Eredmények!$B$5/12*(1+Eredmények!$B$7)^('Havi számolás'!B51-28) -> 1030441.6 | E51: =H50 -> 3697790.6 | F51: =Eredmények!$B$8*D51 -> 82435.325 | G51: =SUM(E51:F51)*((1+Eredmények!$B$9)^(1/12)-1) -> 13891.61 | H51: =E51+F51+G51 -> 3794117.5
A52: =INT((ROW(A51)-1)/12+2028) -> 2032 | B52: =INT((A52-2004)+(C52-1)/12) -> 28 | C52: =C40 -> 3 | D52: =Eredmények!$B$5/12*(1+Eredmények!$B$7)^('Havi számolás'!B52-28) -> 1030441.6 | E52: =H51 -> 3794117.5 | F52: =Eredmények!$B$8*D52 -> 82435.325 | G52: =SUM(E52:F52)*((1+Eredmények!$B$9)^(1/12)-1) -> 14245.593 | H52: =E52+F52+G52 -> 3890798.4
A53: =INT((ROW(A52)-1)/12+2028) -> 2032 | B53: =INT((A53-2004)+(C53-1)/12) -> 28 | C53: =C41 -> 4 | D53: =Eredmények!$B$5/12*(1+Eredmények!$B$7)^('Havi számolás'!B53-28) -> 1030441.6 | E53: =H52 -> 3890798.4 | F53: =Eredmények!$B$8*D53 -> 82435.325 | G53: =SUM(E53:F53)*((1+Eredmények!$B$9)^(1/12)-1) -> 14600.877 | H53: =E53+F53+G53 -> 3987834.6
A54: =INT((ROW(A53)-1)/12+2028) -> 2032 | B54: =INT((A54-2004)+(C54-1)/12) -> 28 | C54: =C42 -> 5 | D54: =Eredmények!$B$5/12*(1+Eredmények!$B$7)^('Havi számolás'!B54-28) -> 1030441.6 | E54: =H53 -> 3987834.6 | F54: =Eredmények!$B$8*D54 -> 82435.325 | G54: =SUM(E54:F54)*((1+Eredmények!$B$9)^(1/12)-1) -> 14957.466 | H54: =E54+F54+G54 -> 4085227.4
A55: =INT((ROW(A54)-1)/12+2028) -> 2032 | B55: =INT((A55-2004)+(C55-1)/12) -> 28 | C55: =C43 -> 6 | D55: =Eredmények!$B$5/12*(1+Eredmények!$B$7)^('Havi számolás'!B55-28) -> 1030441.6 | E55: =H54 -> 4085227.4 | F55: =Eredmények!$B$8*D55 -> 82435.325 | G55: =SUM(E55:F55)*((1+Eredmények!$B$9)^(1/12)-1) -> 15315.366 | H55: =E55+F55+G55 -> 4182978.1
A56: =INT((ROW(A55)-1)/12+2028) -> 2032 | B56: =INT((A56-2004)+(C56-1)/12) -> 28 | C56: =C44 -> 7 | D56: =Eredmények!$B$5/12*(1+Eredmények!$B$7)^('Havi számolás'!B56-28) -> 1030441.6 | E56: =H55 -> 4182978.1 | F56: =Eredmények!$B$8*D56 -> 82435.325 | G56: =SUM(E56:F56)*((1+Eredmények!$B$9)^(1/12)-1) -> 15674.581 | H56: =E56+F56+G56 -> 4281088
A57: =INT((ROW(A56)-1)/12+2028) -> 2032 | B57: =INT((A57-2004)+(C57-1)/12) -> 28 | C57: =C45 -> 8 | D57: =Eredmények!$B$5/12*(1+Eredmények!$B$7)^('Havi számolás'!B57-28) -> 1030441.6 | E57: =H56 -> 4281088 | F57: =Eredmények!$B$8*D57 -> 82435.325 | G57: =SUM(E57:F57)*((1+Eredmények!$B$9)^(1/12)-1) -> 16035.117 | H57: =E57+F57+G57 -> 4379558.4
A58: =INT((ROW(A57)-1)/12+2028) -> 2032 | B58: =INT((A58-2004)+(C58-1)/12) -> 28 | C58: =C46 -> 9 | D58: =Eredmények!$B$5/12*(1+Eredmények!$B$7)^('Havi számolás'!B58-28) -> 1030441.6 | E58: =H57 -> 4379558.4 | F58: =Eredmények!$B$8*D58 -> 82435.325 | G58: =SUM(E58:F58)*((1+Eredmények!$B$9)^(1/12)-1) -> 16396.977 | H58: =E58+F58+G58 -> 4478390.7
A59: =INT((ROW(A58)-1)/12+2028) -> 2032 | B59: =INT((A59-2004)+(C59-1)/12) -> 28 | C59: =C47 -> 10 | D59: =Eredmények!$B$5/12*(1+Eredmények!$B$7)^('Havi számolás'!B59-28) -> 1030441.6 | E59: =H58 -> 4478390.7 | F59: =Eredmények!$B$8*D59 -> 82435.325 | G59: =SUM(E59:F59)*((1+Eredmények!$B$9)^(1/12)-1) -> 16760.167 | H59: =E59+F59+G59 -> 4577586.2
A60: =INT((ROW(A59)-1)/12+2028) -> 2032 | B60: =INT((A60-2004)+(C60-1)/12) -> 28 | C60: =C48 -> 11 | D60: =Eredmények!$B$5/12*(1+Eredmények!$B$7)^('Havi számolás'!B60-28) -> 1030441.6 | E60: =H59 -> 4577586.2 | F60: =Eredmények!$B$8*D60 -> 82435.325 | G60: =SUM(E60:F60)*((1+Eredmények!$B$9)^(1/12)-1) -> 17124.691 | H60: =E60+F60+G60 -> 4677146.3
A61: =INT((ROW(A60)-1)/12+2028) -> 2032 | B61: =INT((A61-2004)+(C61-1)/12) -> 28 | C61: =C49 -> 12 | D61: =Eredmények!$B$5/12*(1+Eredmények!$B$7)^('Havi számolás'!B61-28) -> 1030441.6 | E61: =H60 -> 4677146.3 | F61: =Eredmények!$B$8*D61 -> 82435.325 | G61: =SUM(E61:F61)*((1+Eredmények!$B$9)^(1/12)-1) -> 17490.555 | H61: =E61+F61+G61 -> 4777072.1
A62: =INT((ROW(A61)-1)/12+2028) -> 2033 | B62: =INT((A62-2004)+(C62-1)/12) -> 29 | C62: =C50 -> 1 | D62: =Eredmények!$B$5/12*(1+Eredmények!$B$7)^('Havi számolás'!B62-28) -> 1061354.8 | E62: =H61 -> 4777072.1 | F62: =Eredmények!$B$8*D62 -> 84908.385 | G62: =SUM(E62:F62)*((1+Eredmények!$B$9)^(1/12)-1) -> 17866.852 | H62: =E62+F62+G62 -> 4879847.4
... A109: =INT((ROW(A108)-1)/12+2028) -> 2036 | B109: =INT((A109-2004)+(C109-1)/12) -> 32 | C109: =C97 -> 12 | D109: =Eredmények!$B$5/12*(1+Eredmények!$B$7)^('Havi számolás'!B109-28) -> 1159771.1 | E109: =H108 -> 10227996 | F109: =Eredmények!$B$8*D109 -> 92781.684 | G109: =SUM(E109:F109)*((1+Eredmények!$B$9)^(1/12)-1) -> 37926.892 | H109: =E109+F109+G109 -> 10358705
...

Sheet Számla egyenleg nyugdíj alatt
A1: Év | B1: Életkor | C1: tp67 | D1: Éves induló nyugdíj | E1: Nyitó Egyenleg | F1: Várható kifizetés | G1: Hozam | H1: Záró Egyenleg
A2: 2071 | B2: 67 | C2: ='Tábla 2020'!F69 -> 1 | D2: =Eredmények!$I$2*12 -> 21208764 | E2: =Eredmények!G2 -> 2.044948e+08 | F2: =-D2*C2 -> -21208764 | G2: =MAX(SUM(E2:F2)*Eredmények!$B$9,0) -> 8247871.7 | H2: =MAX(0,E2+F2+G2) -> 1.9153391e+08
A3: 2072 | B3: 68 | C3: ='Tábla 2020'!F70 -> 0.96419971 | D3: =Eredmények!$I$2*12 -> 21208764 | E3: =H2 -> 1.9153391e+08 | F3: =-D3*C3 -> -20449484 | G3: =MAX(SUM(E3:F3)*Eredmények!$B$9,0) -> 7698799.2 | H3: =MAX(0,E3+F3+G3) -> 1.7878323e+08
A4: 2073 | B4: 69 | C4: ='Tábla 2020'!F71 -> 0.92684288 | D4: =Eredmények!$I$2*12 -> 21208764 | E4: =H3 -> 1.7878323e+08 | F4: =-D4*C4 -> -19657192 | G4: =MAX(SUM(E4:F4)*Eredmények!$B$9,0) -> 7160671.5 | H4: =MAX(0,E4+F4+G4) -> 1.6628671e+08
A5: 2074 | B5: 70 | C5: ='Tábla 2020'!F72 -> 0.88948605 | D5: =Eredmények!$I$2*12 -> 21208764 | E5: =H4 -> 1.6628671e+08 | F5: =-D5*C5 -> -18864899 | G5: =MAX(SUM(E5:F5)*Eredmények!$B$9,0) -> 6633981.3 | H5: =MAX(0,E5+F5+G5) -> 1.5405579e+08
A6: 2075 | B6: 71 | C6: ='Tábla 2020'!F73 -> 0.85286344 | D6: =Eredmények!$I$2*12 -> 21208764 | E6: =H5 -> 1.5405579e+08 | F6: =-D6*C6 -> -18088179 | G6: =MAX(SUM(E6:F6)*Eredmények!$B$9,0) -> 6118542.4 | H6: =MAX(0,E6+F6+G6) -> 1.4208615e+08
A7: 2076 | B7: 72 | C7: ='Tábla 2020'!F74 -> 0.81483113 | D7: =Eredmények!$I$2*12 -> 21208764 | E7: =H6 -> 1.4208615e+08 | F7: =-D7*C7 -> -17281561 | G7: =MAX(SUM(E7:F7)*Eredmények!$B$9,0) -> 5616206.5 | H7: =MAX(0,E7+F7+G7) -> 1.304208e+08
A8: 2077 | B8: 73 | C8: ='Tábla 2020'!F75 -> 0.77409692 | D8: =Eredmények!$I$2*12 -> 21208764 | E8: =H7 -> 1.304208e+08 | F8: =-D8*C8 -> -16417639 | G8: =MAX(SUM(E8:F8)*Eredmények!$B$9,0) -> 5130142.1 | H8: =MAX(0,E8+F8+G8) -> 1.191333e+08
A9: 2078 | B9: 74 | C9: ='Tábla 2020'!F76 -> 0.73375918 | D9: =Eredmények!$I$2*12 -> 21208764 | E9: =H8 -> 1.191333e+08 | F9: =-D9*C9 -> -15562125 | G9: =MAX(SUM(E9:F9)*Eredmények!$B$9,0) -> 4660702.9 | H9: =MAX(0,E9+F9+G9) -> 1.0823188e+08
A10: 2079 | B10: 75 | C10: ='Tábla 2020'!F77 -> 0.69600587 | D10: =Eredmények!$I$2*12 -> 21208764 | E10: =H9 -> 1.0823188e+08 | F10: =-D10*C10 -> -14761424 | G10: =MAX(SUM(E10:F10)*Eredmények!$B$9,0) -> 4206170.4 | H10: =MAX(0,E10+F10+G10) -> 97676624
A11: 2080 | B11: 76 | C11: ='Tábla 2020'!F78 -> 0.65317181 | D11: =Eredmények!$I$2*12 -> 21208764 | E11: =H10 -> 97676624 | F11: =-D11*C11 -> -13852966 | G11: =MAX(SUM(E11:F11)*Eredmények!$B$9,0) -> 3772064.6 | H11: =MAX(0,E11+F11+G11) -> 87595722
A12: 2081 | B12: 77 | C12: ='Tábla 2020'!F79 -> 0.61005874 | D12: =Eredmények!$I$2*12 -> 21208764 | E12: =H11 -> 87595722 | F12: =-D12*C12 -> -12938592 | G12: =MAX(SUM(E12:F12)*Eredmények!$B$9,0) -> 3359570.9 | H12: =MAX(0,E12+F12+G12) -> 78016702
A13: 2082 | B13: 78 | C13: ='Tábla 2020'!F80 -> 0.56845815 | D13: =Eredmények!$I$2*12 -> 21208764 | E13: =H12 -> 78016702 | F13: =-D13*C13 -> -12056295 | G13: =MAX(SUM(E13:F13)*Eredmények!$B$9,0) -> 2968218.3 | H13: =MAX(0,E13+F13+G13) -> 68928626
A14: 2083 | B14: 79 | C14: ='Tábla 2020'!F81 -> 0.52441997 | D14: =Eredmények!$I$2*12 -> 21208764 | E14: =H13 -> 68928626 | F14: =-D14*C14 -> -11122299 | G14: =MAX(SUM(E14:F14)*Eredmények!$B$9,0) -> 2601284.7 | H14: =MAX(0,E14+F14+G14) -> 60407611
... A45: 2114 | B45: 110 | C45: ='Tábla 2020'!F112 -> 2.9368576e-05 | D45: =Eredmények!$I$2*12 -> 21208764 | E45: =H44 -> 0 | F45: =-D45*C45 -> -622.87118 | G45: =MAX(SUM(E45:F45)*Eredmények!$B$9,0) -> 0 | H45: =MAX(0,E45+F45+G45) -> 0

Sheet Érzékenység vizsgálat
A1: Paraméter | B1: Érték | C1: Indoklás | F1: Paraméter | G1: Változtatás | H1: Havi induló nyugdíj | I1: Eltérés | J1: Százalékos eltérés
A2: Munkába állás kora (év) | B2: 24 | C2: diploma megszerzés éve, munkakezdés éve | F2: Összes | G2: Alap | H2: 1767397 | I2: =H2-$H$2 -> 0 | J2: =H2/$H$2-1 -> 0
A3: Nyugdíjkorhatár (év) | B3: 67 | C3: Várható nyugdíjkorhatár, demográfiai kürölményeknek köszönhetően | F3: Egyszeri béremelések | G3: 10%: Medior, Senior | H3: 1589080.5 | I3: =H3-$H$2 -> -178316.46 | J3: =H3/$H$2-1 -> -0.10089214
A4: Junior éves bér (életkor 24-27) | B4: 9840000 | C4: Nyilvános béradatok alapján választott mediánközeli bruttó bér | F4: Egyszeri béremelések | G4: 22%: Medior, Senior | H4: 1888610.7 | I4: =H4-$H$2 -> 121213.76 | J4: =H4/$H$2-1 -> 0.068583211
A5: Medior éves bér (életkor 28-32) | B5: 12365299 | C5: 15%-os egyszeri karrierszintváltási béremelés utáni bruttó bér | F5: Éves bérnövekedés | G5: 2%-ra csökkenés | H5: 1493795.4 | I5: =H5-$H$2 -> -273601.61 | J5: =H5/$H$2-1 -> -0.15480484
A6: Senior éves bér (életkor 33-64) | B6: 16700703 | C6: 20%-os egyszeri karrierszintváltási béremelés utáni bruttó bér | F6: Éves bérnövekedés | G6: 5%-ra emelkedés | H6: 2557483.7 | I6: =H6-$H$2 -> 790086.7 | J6: =H6/$H$2-1 -> 0.44703409
A7: Éves bérnövekedés | B7: 0.03 | C7: Konzervatív, 3%-os középtávú inflációs célhoz közeli érték | F7: Járulékkulcs | G7: 5%-ra csökkenés | H7: 1104623.1 | I7: =H7-$H$2 -> -662773.86 | J7: =H7/$H$2-1 -> -0.375
A8: Járulékkulcs | B8: 0.08 | C8: Modellparaméterként választott, saját célú nyugdíjmegtakarítási ráta | F8: Járulékkulcs | G8: 10%-ra emelés | H8: 2209246.2 | I8: =H8-$H$2 -> 441849.24 | J8: =H8/$H$2-1 -> 0.25
A9: Éves hozam | B9: 0.045 | C9: Konzervatív nominális hozam, a hosszú állampapírhozamok alatt | F9: Éves hozam | G9: 3%-ra csökkenés | H9: 1163433.6 | I9: =H9-$H$2 -> -603963.32 | J9: =H9/$H$2-1 -> -0.34172477
A10: Halandóság | B10: Férfi | C10: 2020-as magyar férfi halandósági tábla alapján | F10: Éves hozam | G10: 6%-ra emelkedés | H10: 2730473.8 | I10: =H10-$H$2 -> 963076.87 | J10: =H10/$H$2-1 -> 0.54491259
F11: Nyugdíjkorhatár | G11: 65 év | H11: 1675563.1 | I11: =H11-$H$2 -> -91833.849 | J11: =H11/$H$2-1 -> -0.051959945
F12: Nyugdíjkorhatár | G12: 69 év | H12: 1873675.1 | I12: =H12-$H$2 -> 106278.08 | J12: =H12/$H$2-1 -> 0.060132545

Sheet Eredmények konzervatív
A1: Paraméter | B1: Érték | C1: Indoklás | F1: Járadéktag | G1: Nyugdíj előtti záró egyenleg | H1: Éves induló nyugdíj | I1: Havi induló nyugdíj
A2: Munkába állás kora | B2: 24 | C2: diploma megszerzés éve, munkakezdés éve | F2: =SUM('Tábla 2020'!H67:H112) -> 9.6420213 | G2: ='Havi számolás konzervatív'!M1 -> 90482854 | H2: =G2/F2 -> 9384220.5 | I2: =H2/12 -> 782018.38
A3: Nyugdíjkorhatár | B3: 67 | C3: Várható nyugdíjkorhatár, demográfiai kürölményeknek köszönhetően
A4: Junior éves bér (életkor 24-27) | B4: =12*820000 -> 9840000 | C4: Pézügyi elemző medián körüli kezdőfizetés
A5: Medior éves bér (életkor 28-30) | B5: ='Havi számolás konzervatív'!D49*12*1.1 -> 11486515 | C5: 10%-os egyszeri béremelkedés
A6: Senior éves bér (életkor 33-64) | B6: ='Havi számolás konzervatív'!D109*12*1.1 -> 13676711 | C6: 10%-os egyszeri béremelés | D6: Változás
A7: Éves kihagyás (életkor 40 év) | B7: 0 | C7: Váratlan 1 éves kihagyás | D7: Változás
A8: Éves bérnövekedés | B8: 0.02 | C8: Konzervatív, 3%-os középtávú inflációs célhoz alatti érték | D8: Változás
A9: Járulékkulcs | B9: 0.06 | C9: Modellparaméterként választott, saját célú nyugdíjmegtakarítási ráta | D9: Változás
A10: Éves hozam | B10: 0.035 | C10: konzervatív, állampapír mai hozamához (6,98%-hoz) képest kisebb | D10: Változás
A11: Halandóság | B11: Férfi | C11: Férfi haladnósági tábla használata

Sheet Havi számolás konzervatív
A1: Év | B1: Életkor | C1: Hónap | D1: Bér | E1: Nyitó Egyenleg | F1: Befizetés | G1: Hozam | H1: Záró Egyenleg | L1: Nyugdíj előtti záró egyenleg | M1: {=LOOKUP(2,1/(H:H<>""),H:H)} -> 90482854
A2: =INT((ROW(A1)-1)/12+2028) -> 2028 | B2: =INT((A2-2004)+(C2-1)/12) -> 24 | C2: 1 | D2: ='Eredmények konzervatív'!$B$4/12*(1+'Eredmények konzervatív'!$B$8)^('Havi számolás konzervatív'!B2-24) -> 820000 | E2: 0 | F2: ='Eredmények konzervatív'!$B$9*D2 -> 49200 | G2: =SUM(E2:F2)*((1+'Eredmények konzervatív'!$B$10)^(1/12)-1) -> 141.24822 | H2: =E2+F2+G2 -> 49341.248
A3: =INT((ROW(A2)-1)/12+2028) -> 2028 | B3: =INT((A3-2004)+(C3-1)/12) -> 24 | C3: 2 | D3: ='Eredmények konzervatív'!$B$4/12*(1+'Eredmények konzervatív'!$B$8)^('Havi számolás konzervatív'!B3-24) -> 820000 | E3: =H2 -> 49341.248 | F3: ='Eredmények konzervatív'!$B$9*D3 -> 49200 | G3: =SUM(E3:F3)*((1+'Eredmények konzervatív'!$B$10)^(1/12)-1) -> 282.90194 | H3: =E3+F3+G3 -> 98824.15
A4: =INT((ROW(A3)-1)/12+2028) -> 2028 | B4: =INT((A4-2004)+(C4-1)/12) -> 24 | C4: 3 | D4: ='Eredmények konzervatív'!$B$4/12*(1+'Eredmények konzervatív'!$B$8)^('Havi számolás konzervatív'!B4-24) -> 820000 | E4: =H3 -> 98824.15 | F4: ='Eredmények konzervatív'!$B$9*D4 -> 49200 | G4: =SUM(E4:F4)*((1+'Eredmények konzervatív'!$B$10)^(1/12)-1) -> 424.96234 | H4: =E4+F4+G4 -> 148449.11
A5: =INT((ROW(A4)-1)/12+2028) -> 2028 | B5: =INT((A5-2004)+(C5-1)/12) -> 24 | C5: 4 | D5: ='Eredmények konzervatív'!$B$4/12*(1+'Eredmények konzervatív'!$B$8)^('Havi számolás konzervatív'!B5-24) -> 820000 | E5: =H4 -> 148449.11 | F5: ='Eredmények konzervatív'!$B$9*D5 -> 49200 | G5: =SUM(E5:F5)*((1+'Eredmények konzervatív'!$B$10)^(1/12)-1) -> 567.43058 | H5: =E5+F5+G5 -> 198216.54
A6: =INT((ROW(A5)-1)/12+2028) -> 2028 | B6: =INT((A6-2004)+(C6-1)/12) -> 24 | C6: 5 | D6: ='Eredmények konzervatív'!$B$4/12*(1+'Eredmények konzervatív'!$B$8)^('Havi számolás konzervatív'!B6-24) -> 820000 | E6: =H5 -> 198216.54 | F6: ='Eredmények konzervatív'!$B$9*D6 -> 49200 | G6: =SUM(E6:F6)*((1+'Eredmények konzervatív'!$B$10)^(1/12)-1) -> 710.30784 | H6: =E6+F6+G6 -> 248126.85
A7: =INT((ROW(A6)-1)/12+2028) -> 2028 | B7: =INT((A7-2004)+(C7-1)/12) -> 24 | C7: 6 | D7: ='Eredmények konzervatív'!$B$4/12*(1+'Eredmények konzervatív'!$B$8)^('Havi számolás konzervatív'!B7-24) -> 820000 | E7: =H6 -> 248126.85 | F7: ='Eredmények konzervatív'!$B$9*D7 -> 49200 | G7: =SUM(E7:F7)*((1+'Eredmények konzervatív'!$B$10)^(1/12)-1) -> 853.59528 | H7: =E7+F7+G7 -> 298180.45
A8: =INT((ROW(A7)-1)/12+2028) -> 2028 | B8: =INT((A8-2004)+(C8-1)/12) -> 24 | C8: 7 | D8: ='Eredmények konzervatív'!$B$4/12*(1+'Eredmények konzervatív'!$B$8)^('Havi számolás konzervatív'!B8-24) -> 820000 | E8: =H7 -> 298180.45 | F8: ='Eredmények konzervatív'!$B$9*D8 -> 49200 | G8: =SUM(E8:F8)*((1+'Eredmények konzervatív'!$B$10)^(1/12)-1) -> 997.29408 | H8: =E8+F8+G8 -> 348377.74
A9: =INT((ROW(A8)-1)/12+2028) -> 2028 | B9: =INT((A9-2004)+(C9-1)/12) -> 24 | C9: 8 | D9: ='Eredmények konzervatív'!$B$4/12*(1+'Eredmények konzervatív'!$B$8)^('Havi számolás konzervatív'!B9-24) -> 820000 | E9: =H8 -> 348377.74 | F9: ='Eredmények konzervatív'!$B$9*D9 -> 49200 | G9: =SUM(E9:F9)*((1+'Eredmények konzervatív'!$B$10)^(1/12)-1) -> 1141.4054 | H9: =E9+F9+G9 -> 398719.15
A10: =INT((ROW(A9)-1)/12+2028) -> 2028 | B10: =INT((A10-2004)+(C10-1)/12) -> 24 | C10: 9 | D10: ='Eredmények konzervatív'!$B$4/12*(1+'Eredmények konzervatív'!$B$8)^('Havi számolás konzervatív'!B10-24) -> 820000 | E10: =H9 -> 398719.15 | F10: ='Eredmények konzervatív'!$B$9*D10 -> 49200 | G10: =SUM(E10:F10)*((1+'Eredmények konzervatív'!$B$10)^(1/12)-1) -> 1285.9305 | H10: =E10+F10+G10 -> 449205.08
A11: =INT((ROW(A10)-1)/12+2028) -> 2028 | B11: =INT((A11-2004)+(C11-1)/12) -> 24 | C11: 10 | D11: ='Eredmények konzervatív'!$B$4/12*(1+'Eredmények konzervatív'!$B$8)^('Havi számolás konzervatív'!B11-24) -> 820000 | E11: =H10 -> 449205.08 | F11: ='Eredmények konzervatív'!$B$9*D11 -> 49200 | G11: =SUM(E11:F11)*((1+'Eredmények konzervatív'!$B$10)^(1/12)-1) -> 1430.8705 | H11: =E11+F11+G11 -> 499835.95
A12: =INT((ROW(A11)-1)/12+2028) -> 2028 | B12: =INT((A12-2004)+(C12-1)/12) -> 24 | C12: 11 | D12: ='Eredmények konzervatív'!$B$4/12*(1+'Eredmények konzervatív'!$B$8)^('Havi számolás konzervatív'!B12-24) -> 820000 | E12: =H11 -> 499835.95 | F12: ='Eredmények konzervatív'!$B$9*D12 -> 49200 | G12: =SUM(E12:F12)*((1+'Eredmények konzervatív'!$B$10)^(1/12)-1) -> 1576.2266 | H12: =E12+F12+G12 -> 550612.17
A13: =INT((ROW(A12)-1)/12+2028) -> 2028 | B13: =INT((A13-2004)+(C13-1)/12) -> 24 | C13: 12 | D13: ='Eredmények konzervatív'!$B$4/12*(1+'Eredmények konzervatív'!$B$8)^('Havi számolás konzervatív'!B13-24) -> 820000 | E13: =H12 -> 550612.17 | F13: ='Eredmények konzervatív'!$B$9*D13 -> 49200 | G13: =SUM(E13:F13)*((1+'Eredmények konzervatív'!$B$10)^(1/12)-1) -> 1722 | H13: =E13+F13+G13 -> 601534.17
A14: =INT((ROW(A13)-1)/12+2028) -> 2029 | B14: =INT((A14-2004)+(C14-1)/12) -> 25 | C14: =C2 -> 1 | D14: ='Eredmények konzervatív'!$B$4/12*(1+'Eredmények konzervatív'!$B$8)^('Havi számolás konzervatív'!B14-24) -> 836400 | E14: =H13 -> 601534.17 | F14: ='Eredmények konzervatív'!$B$9*D14 -> 50184 | G14: =SUM(E14:F14)*((1+'Eredmények konzervatív'!$B$10)^(1/12)-1) -> 1871.0169 | H14: =E14+F14+G14 -> 653589.19
A15: =INT((ROW(A14)-1)/12+2028) -> 2029 | B15: =INT((A15-2004)+(C15-1)/12) -> 25 | C15: =C3 -> 2 | D15: ='Eredmények konzervatív'!$B$4/12*(1+'Eredmények konzervatív'!$B$8)^('Havi számolás konzervatív'!B15-24) -> 836400 | E15: =H14 -> 653589.19 | F15: ='Eredmények konzervatív'!$B$9*D15 -> 50184 | G15: =SUM(E15:F15)*((1+'Eredmények konzervatív'!$B$10)^(1/12)-1) -> 2020.4616 | H15: =E15+F15+G15 -> 705793.65
A16: =INT((ROW(A15)-1)/12+2028) -> 2029 | B16: =INT((A16-2004)+(C16-1)/12) -> 25 | C16: =C4 -> 3 | D16: ='Eredmények konzervatív'!$B$4/12*(1+'Eredmények konzervatív'!$B$8)^('Havi számolás konzervatív'!B16-24) -> 836400 | E16: =H15 -> 705793.65 | F16: ='Eredmények konzervatív'!$B$9*D16 -> 50184 | G16: =SUM(E16:F16)*((1+'Eredmények konzervatív'!$B$10)^(1/12)-1) -> 2170.3353 | H16: =E16+F16+G16 -> 758147.99
A17: =INT((ROW(A16)-1)/12+2028) -> 2029 | B17: =INT((A17-2004)+(C17-1)/12) -> 25 | C17: =C5 -> 4 | D17: ='Eredmények konzervatív'!$B$4/12*(1+'Eredmények konzervatív'!$B$8)^('Havi számolás konzervatív'!B17-24) -> 836400 | E17: =H16 -> 758147.99 | F17: ='Eredmények konzervatív'!$B$9*D17 -> 50184 | G17: =SUM(E17:F17)*((1+'Eredmények konzervatív'!$B$10)^(1/12)-1) -> 2320.6393 | H17: =E17+F17+G17 -> 810652.63
A18: =INT((ROW(A17)-1)/12+2028) -> 2029 | B18: =INT((A18-2004)+(C18-1)/12) -> 25 | C18: =C6 -> 5 | D18: ='Eredmények konzervatív'!$B$4/12*(1+'Eredmények konzervatív'!$B$8)^('Havi számolás konzervatív'!B18-24) -> 836400 | E18: =H17 -> 810652.63 | F18: ='Eredmények konzervatív'!$B$9*D18 -> 50184 | G18: =SUM(E18:F18)*((1+'Eredmények konzervatív'!$B$10)^(1/12)-1) -> 2471.3748 | H18: =E18+F18+G18 -> 863308
A19: =INT((ROW(A18)-1)/12+2028) -> 2029 | B19: =INT((A19-2004)+(C19-1)/12) -> 25 | C19: =C7 -> 6 | D19: ='Eredmények konzervatív'!$B$4/12*(1+'Eredmények konzervatív'!$B$8)^('Havi számolás konzervatív'!B19-24) -> 836400 | E19: =H18 -> 863308 | F19: ='Eredmények konzervatív'!$B$9*D19 -> 50184 | G19: =SUM(E19:F19)*((1+'Eredmények konzervatív'!$B$10)^(1/12)-1) -> 2622.543 | H19: =E19+F19+G19 -> 916114.54
A20: =INT((ROW(A19)-1)/12+2028) -> 2029 | B20: =INT((A20-2004)+(C20-1)/12) -> 25 | C20: =C8 -> 7 | D20: ='Eredmények konzervatív'!$B$4/12*(1+'Eredmények konzervatív'!$B$8)^('Havi számolás konzervatív'!B20-24) -> 836400 | E20: =H19 -> 916114.54 | F20: ='Eredmények konzervatív'!$B$9*D20 -> 50184 | G20: =SUM(E20:F20)*((1+'Eredmények konzervatív'!$B$10)^(1/12)-1) -> 2774.1453 | H20: =E20+F20+G20 -> 969072.69
A21: =INT((ROW(A20)-1)/12+2028) -> 2029 | B21: =INT((A21-2004)+(C21-1)/12) -> 25 | C21: =C9 -> 8 | D21: ='Eredmények konzervatív'!$B$4/12*(1+'Eredmények konzervatív'!$B$8)^('Havi számolás konzervatív'!B21-24) -> 836400 | E21: =H20 -> 969072.69 | F21: ='Eredmények konzervatív'!$B$9*D21 -> 50184 | G21: =SUM(E21:F21)*((1+'Eredmények konzervatív'!$B$10)^(1/12)-1) -> 2926.1827 | H21: =E21+F21+G21 -> 1022182.9
A22: =INT((ROW(A21)-1)/12+2028) -> 2029 | B22: =INT((A22-2004)+(C22-1)/12) -> 25 | C22: =C10 -> 9 | D22: ='Eredmények konzervatív'!$B$4/12*(1+'Eredmények konzervatív'!$B$8)^('Havi számolás konzervatív'!B22-24) -> 836400 | E22: =H21 -> 1022182.9 | F22: ='Eredmények konzervatív'!$B$9*D22 -> 50184 | G22: =SUM(E22:F22)*((1+'Eredmények konzervatív'!$B$10)^(1/12)-1) -> 3078.6567 | H22: =E22+F22+G22 -> 1075445.5
A23: =INT((ROW(A22)-1)/12+2028) -> 2029 | B23: =INT((A23-2004)+(C23-1)/12) -> 25 | C23: =C11 -> 10 | D23: ='Eredmények konzervatív'!$B$4/12*(1+'Eredmények konzervatív'!$B$8)^('Havi számolás konzervatív'!B23-24) -> 836400 | E23: =H22 -> 1075445.5 | F23: ='Eredmények konzervatív'!$B$9*D23 -> 50184 | G23: =SUM(E23:F23)*((1+'Eredmények konzervatív'!$B$10)^(1/12)-1) -> 3231.5684 | H23: =E23+F23+G23 -> 1128861.1
A24: =INT((ROW(A23)-1)/12+2028) -> 2029 | B24: =INT((A24-2004)+(C24-1)/12) -> 25 | C24: =C12 -> 11 | D24: ='Eredmények konzervatív'!$B$4/12*(1+'Eredmények konzervatív'!$B$8)^('Havi számolás konzervatív'!B24-24) -> 836400 | E24: =H23 -> 1128861.1 | F24: ='Eredmények konzervatív'!$B$9*D24 -> 50184 | G24: =SUM(E24:F24)*((1+'Eredmények konzervatív'!$B$10)^(1/12)-1) -> 3384.9191 | H24: =E24+F24+G24 -> 1182430
A25: =INT((ROW(A24)-1)/12+2028) -> 2029 | B25: =INT((A25-2004)+(C25-1)/12) -> 25 | C25: =C13 -> 12 | D25: ='Eredmények konzervatív'!$B$4/12*(1+'Eredmények konzervatív'!$B$8)^('Havi számolás konzervatív'!B25-24) -> 836400 | E25: =H24 -> 1182430 | F25: ='Eredmények konzervatív'!$B$9*D25 -> 50184 | G25: =SUM(E25:F25)*((1+'Eredmények konzervatív'!$B$10)^(1/12)-1) -> 3538.71 | H25: =E25+F25+G25 -> 1236152.7
... A49: =INT((ROW(A48)-1)/12+2028) -> 2031 | B49: =INT((A49-2004)+(C49-1)/12) -> 27 | C49: =C37 -> 12 | D49: ='Eredmények konzervatív'!$B$4/12*(1+'Eredmények konzervatív'!$B$8)^('Havi számolás konzervatív'!B49-24) -> 870190.56 | E49: =H48 -> 2550607.1 | F49: ='Eredmények konzervatív'!$B$9*D49 -> 52211.434 | G49: =SUM(E49:F49)*((1+'Eredmények konzervatív'!$B$10)^(1/12)-1) -> 7472.4285 | H49: =E49+F49+G49 -> 2610291
A50: =INT((ROW(A49)-1)/12+2028) -> 2032 | B50: =INT((A50-2004)+(C50-1)/12) -> 28 | C50: =C38 -> 1 | D50: ='Eredmények konzervatív'!$B$5/12*(1+'Eredmények konzervatív'!$B$8)^('Havi számolás konzervatív'!B50-28) -> 957209.62 | E50: =H49 -> 2610291 | F50: ='Eredmények konzervatív'!$B$9*D50 -> 57432.577 | G50: =SUM(E50:F50)*((1+'Eredmények konzervatív'!$B$10)^(1/12)-1) -> 7658.7642 | H50: =E50+F50+G50 -> 2675382.3 | J50: Medior béremelkedés: 15%
A51: =INT((ROW(A50)-1)/12+2028) -> 2032 | B51: =INT((A51-2004)+(C51-1)/12) -> 28 | C51: =C39 -> 2 | D51: ='Eredmények konzervatív'!$B$5/12*(1+'Eredmények konzervatív'!$B$8)^('Havi számolás konzervatív'!B51-28) -> 957209.62 | E51: =H50 -> 2675382.3 | F51: ='Eredmények konzervatív'!$B$9*D51 -> 57432.577 | G51: =SUM(E51:F51)*((1+'Eredmények konzervatív'!$B$10)^(1/12)-1) -> 7845.6348 | H51: =E51+F51+G51 -> 2740660.6
A52: =INT((ROW(A51)-1)/12+2028) -> 2032 | B52: =INT((A52-2004)+(C52-1)/12) -> 28 | C52: =C40 -> 3 | D52: ='Eredmények konzervatív'!$B$5/12*(1+'Eredmények konzervatív'!$B$8)^('Havi számolás konzervatív'!B52-28) -> 957209.62 | E52: =H51 -> 2740660.6 | F52: ='Eredmények konzervatív'!$B$9*D52 -> 57432.577 | G52: =SUM(E52:F52)*((1+'Eredmények konzervatív'!$B$10)^(1/12)-1) -> 8033.042 | H52: =E52+F52+G52 -> 2806126.2
A53: =INT((ROW(A52)-1)/12+2028) -> 2032 | B53: =INT((A53-2004)+(C53-1)/12) -> 28 | C53: =C41 -> 4 | D53: ='Eredmények konzervatív'!$B$5/12*(1+'Eredmények konzervatív'!$B$8)^('Havi számolás konzervatív'!B53-28) -> 957209.62 | E53: =H52 -> 2806126.2 | F53: ='Eredmények konzervatív'!$B$9*D53 -> 57432.577 | G53: =SUM(E53:F53)*((1+'Eredmények konzervatív'!$B$10)^(1/12)-1) -> 8220.9871 | H53: =E53+F53+G53 -> 2871779.7
A54: =INT((ROW(A53)-1)/12+2028) -> 2032 | B54: =INT((A54-2004)+(C54-1)/12) -> 28 | C54: =C42 -> 5 | D54: ='Eredmények konzervatív'!$B$5/12*(1+'Eredmények konzervatív'!$B$8)^('Havi számolás konzervatív'!B54-28) -> 957209.62 | E54: =H53 -> 2871779.7 | F54: ='Eredmények konzervatív'!$B$9*D54 -> 57432.577 | G54: =SUM(E54:F54)*((1+'Eredmények konzervatív'!$B$10)^(1/12)-1) -> 8409.4719 | H54: =E54+F54+G54 -> 2937621.8
A55: =INT((ROW(A54)-1)/12+2028) -> 2032 | B55: =INT((A55-2004)+(C55-1)/12) -> 28 | C55: =C43 -> 6 | D55: ='Eredmények konzervatív'!$B$5/12*(1+'Eredmények konzervatív'!$B$8)^('Havi számolás konzervatív'!B55-28) -> 957209.62 | E55: =H54 -> 2937621.8 | F55: ='Eredmények konzervatív'!$B$9*D55 -> 57432.577 | G55: =SUM(E55:F55)*((1+'Eredmények konzervatív'!$B$10)^(1/12)-1) -> 8598.4977 | H55: =E55+F55+G55 -> 3003652.9
A56: =INT((ROW(A55)-1)/12+2028) -> 2032 | B56: =INT((A56-2004)+(C56-1)/12) -> 28 | C56: =C44 -> 7 | D56: ='Eredmények konzervatív'!$B$5/12*(1+'Eredmények konzervatív'!$B$8)^('Havi számolás konzervatív'!B56-28) -> 957209.62 | E56: =H55 -> 3003652.9 | F56: ='Eredmények konzervatív'!$B$9*D56 -> 57432.577 | G56: =SUM(E56:F56)*((1+'Eredmények konzervatív'!$B$10)^(1/12)-1) -> 8788.0663 | H56: =E56+F56+G56 -> 3069873.5
A57: =INT((ROW(A56)-1)/12+2028) -> 2032 | B57: =INT((A57-2004)+(C57-1)/12) -> 28 | C57: =C45 -> 8 | D57: ='Eredmények konzervatív'!$B$5/12*(1+'Eredmények konzervatív'!$B$8)^('Havi számolás konzervatív'!B57-28) -> 957209.62 | E57: =H56 -> 3069873.5 | F57: ='Eredmények konzervatív'!$B$9*D57 -> 57432.577 | G57: =SUM(E57:F57)*((1+'Eredmények konzervatív'!$B$10)^(1/12)-1) -> 8978.179 | H57: =E57+F57+G57 -> 3136284.3
A58: =INT((ROW(A57)-1)/12+2028) -> 2032 | B58: =INT((A58-2004)+(C58-1)/12) -> 28 | C58: =C46 -> 9 | D58: ='Eredmények konzervatív'!$B$5/12*(1+'Eredmények konzervatív'!$B$8)^('Havi számolás konzervatív'!B58-28) -> 957209.62 | E58: =H57 -> 3136284.3 | F58: ='Eredmények konzervatív'!$B$9*D58 -> 57432.577 | G58: =SUM(E58:F58)*((1+'Eredmények konzervatív'!$B$10)^(1/12)-1) -> 9168.8376 | H58: =E58+F58+G58 -> 3202885.7
A59: =INT((ROW(A58)-1)/12+2028) -> 2032 | B59: =INT((A59-2004)+(C59-1)/12) -> 28 | C59: =C47 -> 10 | D59: ='Eredmények konzervatív'!$B$5/12*(1+'Eredmények konzervatív'!$B$8)^('Havi számolás konzervatív'!B59-28) -> 957209.62 | E59: =H58 -> 3202885.7 | F59: ='Eredmények konzervatív'!$B$9*D59 -> 57432.577 | G59: =SUM(E59:F59)*((1+'Eredmények konzervatív'!$B$10)^(1/12)-1) -> 9360.0435 | H59: =E59+F59+G59 -> 3269678.3
A60: =INT((ROW(A59)-1)/12+2028) -> 2032 | B60: =INT((A60-2004)+(C60-1)/12) -> 28 | C60: =C48 -> 11 | D60: ='Eredmények konzervatív'!$B$5/12*(1+'Eredmények konzervatív'!$B$8)^('Havi számolás konzervatív'!B60-28) -> 957209.62 | E60: =H59 -> 3269678.3 | F60: ='Eredmények konzervatív'!$B$9*D60 -> 57432.577 | G60: =SUM(E60:F60)*((1+'Eredmények konzervatív'!$B$10)^(1/12)-1) -> 9551.7983 | H60: =E60+F60+G60 -> 3336662.7
A61: =INT((ROW(A60)-1)/12+2028) -> 2032 | B61: =INT((A61-2004)+(C61-1)/12) -> 28 | C61: =C49 -> 12 | D61: ='Eredmények konzervatív'!$B$5/12*(1+'Eredmények konzervatív'!$B$8)^('Havi számolás konzervatív'!B61-28) -> 957209.62 | E61: =H60 -> 3336662.7 | F61: ='Eredmények konzervatív'!$B$9*D61 -> 57432.577 | G61: =SUM(E61:F61)*((1+'Eredmények konzervatív'!$B$10)^(1/12)-1) -> 9744.1037 | H61: =E61+F61+G61 -> 3403839.3
A62: =INT((ROW(A61)-1)/12+2028) -> 2033 | B62: =INT((A62-2004)+(C62-1)/12) -> 29 | C62: =C50 -> 1 | D62: ='Eredmények konzervatív'!$B$5/12*(1+'Eredmények konzervatív'!$B$8)^('Havi számolás konzervatív'!B62-28) -> 976353.81 | E62: =H61 -> 3403839.3 | F62: ='Eredmények konzervatív'!$B$9*D62 -> 58581.228 | G62: =SUM(E62:F62)*((1+'Eredmények konzervatív'!$B$10)^(1/12)-1) -> 9940.2588 | H62: =E62+F62+G62 -> 3472360.8
... A109: =INT((ROW(A108)-1)/12+2028) -> 2036 | B109: =INT((A109-2004)+(C109-1)/12) -> 32 | C109: =C97 -> 12 | D109: ='Eredmények konzervatív'!$B$5/12*(1+'Eredmények konzervatív'!$B$8)^('Havi számolás konzervatív'!B109-28) -> 1036114.5 | E109: =H108 -> 6931747.5 | F109: ='Eredmények konzervatív'!$B$9*D109 -> 62166.868 | G109: =SUM(E109:F109)*((1+'Eredmények konzervatív'!$B$10)^(1/12)-1) -> 20078.82 | H109: =E109+F109+G109 -> 7013993.2
...

Sheet Tábla 2020
A1: Year | B1: Age | C1: lx | D1: qx | E1: px | F1: px_67 | G1: v_67 | H1: px_67*v_67 | I1: px_65 | J1: v_65 | K1: px_65*v_65 | L1: px_69 | M1: v_69 | N1: px_69*v_69
A2: 2020 | B2: 0 | C2: 100000 | D2: =1-C3/C2 -> 0.00404 | E2: =C3/C2 -> 0.99596 | Q2: Nyugdíjkorhatár | R2: Járadéktag
A3: 2020 | B3: 1 | C3: 99596 | D3: =1-C4/C3 -> 0.00014056789 | E3: =C4/C3 -> 0.99985943 | Q3: 65 év | R3: =SUM(K:K) -> 10.170452 | V3: Megjegyzések:
A4: 2020 | B4: 2 | C4: 99582 | D4: =1-C5/C4 -> 0.00013054568 | E4: =C5/C4 -> 0.99986945 | Q4: 67 év | R4: =SUM(H:H) -> 9.6420213 | V4: Magyarországon élő férfi népesség halandósági táblájának 2020-ra vontakozó részlete
A5: 2020 | B5: 3 | C5: 99569 | D5: =1-C6/C5 -> 6.0259719e-05 | E5: =C6/C5 -> 0.99993974 | Q5: 69 év | R5: =SUM(N:N) -> 9.0950848 | V5: Fontos értékek | W5: Age | X5: Életkor
A6: 2020 | B6: 4 | C6: 99563 | D6: =1-C7/C6 -> 0.00010043892 | E6: =C7/C6 -> 0.99989956 | W6: lx | X6: az adott életkort megérők száma egy standard népességből
A7: 2020 | B7: 5 | C7: 99553 | D7: =1-C8/C7 -> 0.00012053881 | E7: =C8/C7 -> 0.99987946 | W7: qx | X7: egyéves halálozási valószínűség
A8: 2020 | B8: 6 | C8: 99541 | D8: =1-C9/C8 -> 0.00011050723 | E8: =C9/C8 -> 0.99988949 | W8: px=1-qx | X8: egyéves túlélési valószínűség
A9: 2020 | B9: 7 | C9: 99530 | D9: =1-C10/C9 -> 8.0377776e-05 | E9: =C10/C9 -> 0.99991962 | W9: px67 | X9: a 67 éves kortól vett kumulált túlélési valószínűség
A10: 2020 | B10: 8 | C10: 99522 | D10: =1-C11/C10 -> 0.00020096059 | E10: =C11/C10 -> 0.99979904 | W10: v_67 | X10: a 67 éves kortól vett diszkontfaktor
A11: 2020 | B11: 9 | C11: 99502 | D11: =1-C12/C11 -> 6.0300295e-05 | E11: =C12/C11 -> 0.9999397 | W11: px_67*v_67 | X11: a járadéktag egyes tagjai
A12: 2020 | B12: 10 | C12: 99496 | D12: =1-C13/C12 -> 4.0202621e-05 | E12: =C13/C12 -> 0.9999598
A13: 2020 | B13: 11 | C13: 99492 | D13: =1-C14/C13 -> 6.0306356e-05 | E13: =C14/C13 -> 0.99993969 | V13: A 2020-as magyar férfi halandósági tábla alapján számított túlélési valószínűségek és diszkontált értékek. A 65, 67 és 69 éves nyugdíjba lépési korhoz tartozó járadéktag ezek összegeként adódik.
A14: 2020 | B14: 12 | C14: 99486 | D14: =1-C15/C14 -> 0.00010051666 | E14: =C15/C14 -> 0.99989948
A15: 2020 | B15: 13 | C15: 99476 | D15: =1-C16/C15 -> 0.00012063211 | E15: =C16/C15 -> 0.99987937
A16: 2020 | B16: 14 | C16: 99464 | D16: =1-C17/C16 -> 0.00015080833 | E16: =C17/C16 -> 0.99984919
A17: 2020 | B17: 15 | C17: 99449 | D17: =1-C18/C17 -> 0.0001809973 | E17: =C18/C17 -> 0.999819 | V17: Az alapmodellemhez a 67 éves nyugdíjkorhatárt hazsnáltam és a járadéktag kiszámításához aktuáriusi logikát követtem.
A18: 2020 | B18: 16 | C18: 99431 | D18: =1-C19/C18 -> 0.00028160232 | E18: =C19/C18 -> 0.9997184
A19: 2020 | B19: 17 | C19: 99403 | D19: =1-C20/C19 -> 0.00043258252 | E19: =C20/C19 -> 0.99956742
A20: 2020 | B20: 18 | C20: 99360 | D20: =1-C21/C20 -> 0.0004126409 | E20: =C21/C20 -> 0.99958736 | V20: A 65 és 69 éves nyugdíjkorhatár használata az érzékenységvizsgálathoz volt szükséges
A21: 2020 | B21: 19 | C21: 99319 | D21: =1-C22/C21 -> 0.00049335978 | E21: =C22/C21 -> 0.99950664
A22: 2020 | B22: 20 | C22: 99270 | D22: =1-C23/C22 -> 0.00075551526 | E22: =C23/C22 -> 0.99924448
A23: 2020 | B23: 21 | C23: 99195 | D23: =1-C24/C23 -> 0.00054438228 | E23: =C24/C23 -> 0.99945562
A24: 2020 | B24: 22 | C24: 99141 | D24: =1-C25/C24 -> 0.00048415893 | E24: =C25/C24 -> 0.99951584
A25: 2020 | B25: 23 | C25: 99093 | D25: =1-C26/C25 -> 0.00056512569 | E25: =C26/C25 -> 0.99943487
A26: 2020 | B26: 24 | C26: 99037 | D26: =1-C27/C26 -> 0.00060583418 | E26: =C27/C26 -> 0.99939417
A27: 2020 | B27: 25 | C27: 98977 | D27: =1-C28/C27 -> 0.00056578801 | E27: =C28/C27 -> 0.99943421
A28: 2020 | B28: 26 | C28: 98921 | D28: =1-C29/C28 -> 0.00069752631 | E28: =C29/C28 -> 0.99930247
A29: 2020 | B29: 27 | C29: 98852 | D29: =1-C30/C29 -> 0.00067778093 | E29: =C30/C29 -> 0.99932222
A30: 2020 | B30: 28 | C30: 98785 | D30: =1-C31/C30 -> 0.00075922458 | E30: =C31/C30 -> 0.99924078
A31: 2020 | B31: 29 | C31: 98710 | D31: =1-C32/C31 -> 0.0011245061 | E31: =C32/C31 -> 0.99887549
A32: 2020 | B32: 30 | C32: 98599 | D32: =1-C33/C32 -> 0.0007606568 | E32: =C33/C32 -> 0.99923934
... A66: 2020 | B66: 64 | C66: 75295 | D66: =1-C67/C66 -> 0.031409788 | E66: =C67/C66 -> 0.96859021
A67: 2020 | B67: 65 | C67: 72930 | D67: =1-C68/C67 -> 0.032620321 | E67: =C68/C67 -> 0.96737968 | I67: =C67/$C$67 -> 1 | J67: 1 | K67: =I67*J67 -> 1
A68: 2020 | B68: 66 | C68: 70551 | D68: =1-C69/C68 -> 0.034740826 | E68: =C69/C68 -> 0.96525917 | I68: =C68/$C$67 -> 0.96737968 | J68: =1/(1+Eredmények!B9) -> 0.9569378 | K68: =I68*J68 -> 0.92572218
A69: 2020 | B69: 67 | C69: 68100 | D69: =1-C70/C69 -> 0.035800294 | E69: =C70/C69 -> 0.96419971 | F69: =C69/$C$69 -> 1 | G69: 1 | H69: =F69*G69 -> 1 | I69: =C69/$C$67 -> 0.93377211 | J69: =J68*$J$68 -> 0.91572995 | K69: =I69*J69 -> 0.85508309
A70: 2020 | B70: 68 | C70: 65662 | D70: =1-C71/C70 -> 0.03874387 | E70: =C71/C70 -> 0.96125613 | F70: =C70/$C$69 -> 0.96419971 | G70: =1/(1+Eredmények!B9) -> 0.9569378 | H70: =F70*G70 -> 0.92267914 | I70: =C70/$C$67 -> 0.90034279 | J70: =J69*$J$68 -> 0.8762966 | K70: =I70*J70 -> 0.78896733
A71: 2020 | B71: 69 | C71: 63118 | D71: =1-C72/C71 -> 0.04030546 | E71: =C72/C71 -> 0.95969454 | F71: =C71/$C$69 -> 0.92684288 | G71: =G70*$G$70 -> 0.91572995 | H71: =F71*G71 -> 0.84873778 | I71: =C71/$C$67 -> 0.86546003 | J71: =J70*$J$68 -> 0.83856134 | K71: =I71*J71 -> 0.72574133 | L71: =C71/$C$71 -> 1 | M71: 1 | N71: =L71*M71 -> 1
A72: 2020 | B72: 70 | C72: 60574 | D72: =1-C73/C72 -> 0.04117278 | E72: =C73/C72 -> 0.95882722 | F72: =C72/$C$69 -> 0.88948605 | G72: =G71*$G$70 -> 0.8762966 | H72: =F72*G72 -> 0.7794536 | I72: =C72/$C$67 -> 0.83057727 | J72: =J71*$J$68 -> 0.80245105 | K72: =I72*J72 -> 0.6664976 | L72: =C72/$C$71 -> 0.95969454 | M72: =1/(1+Eredmények!B9) -> 0.9569378 | N72: =L72*M72 -> 0.91836798
A73: 2020 | B73: 71 | C73: 58080 | D73: =1-C74/C73 -> 0.044593664 | E73: =C74/C73 -> 0.95540634 | F73: =C73/$C$69 -> 0.85286344 | G73: =G72*$G$70 -> 0.83856134 | H73: =F73*G73 -> 0.71517831 | I73: =C73/$C$67 -> 0.79638009 | J73: =J72*$J$68 -> 0.76789574 | K73: =I73*J73 -> 0.61153688 | L73: =C73/$C$71 -> 0.92018125 | M73: =M72*$M$72 -> 0.91572995 | N73: =L73*M73 -> 0.84263753
...

Sheet Teljes Tábla
A1: Magyarországon élő férfi népesség halandósági táblája 1950 és 2020 között | N1: Forrás: | O1: Human Mortality Database, Hungary, Life tables (period 1x1), Males, 1950–2020
O2: Mortiality.org
A3: Year | B3: Age | C3: mx | D3: qx | E3: ax | F3: lx | G3: dx | H3: Lx | I3: Tx
A4: 1950 | B4: 0 | C4: 0.09971 | D4: 0.0932 | E4: 0.3 | F4: 100000 | G4: 9320 | H4: 93468 | I4: 5993031
A5: 1950 | B5: 1 | C5: 0.00756 | D5: 0.00753 | E5: 0.5 | F5: 90680 | G5: 683 | H5: 90339 | I5: 5899563
A6: 1950 | B6: 2 | C6: 0.00348 | D6: 0.00347 | E6: 0.5 | F6: 89997 | G6: 313 | H6: 89841 | I6: 5809224
A7: 1950 | B7: 3 | C7: 0.00278 | D7: 0.00277 | E7: 0.5 | F7: 89685 | G7: 249 | H7: 89560 | I7: 5719383
A8: 1950 | B8: 4 | C8: 0.00198 | D8: 0.00198 | E8: 0.5 | F8: 89436 | G8: 177 | H8: 89348 | I8: 5629823
A9: 1950 | B9: 5 | C9: 0.00149 | D9: 0.00149 | E9: 0.5 | F9: 89259 | G9: 133 | H9: 89193 | I9: 5540475
A10: 1950 | B10: 6 | C10: 0.00172 | D10: 0.00172 | E10: 0.5 | F10: 89126 | G10: 153 | H10: 89050 | I10: 5451283
A11: 1950 | B11: 7 | C11: 0.00118 | D11: 0.00118 | E11: 0.5 | F11: 88973 | G11: 105 | H11: 88921 | I11: 5362233
A12: 1950 | B12: 8 | C12: 0.00133 | D12: 0.00132 | E12: 0.5 | F12: 88868 | G12: 118 | H12: 88810 | I12: 5273312
A13: 1950 | B13: 9 | C13: 0.00118 | D13: 0.00118 | E13: 0.5 | F13: 88751 | G13: 105 | H13: 88698 | I13: 5184503
A14: 1950 | B14: 10 | C14: 0.00115 | D14: 0.00115 | E14: 0.5 | F14: 88646 | G14: 102 | H14: 88595 | I14: 5095804
A15: 1950 | B15: 11 | C15: 0.00116 | D15: 0.00116 | E15: 0.5 | F15: 88544 | G15: 103 | H15: 88493 | I15: 5007209
... A113: 1950 | B113: 109 | C113: 0.80215 | D113: 0.57252 | E113: 0.5 | F113: 0 | G113: 0 | H113: 0 | I113: 0
A114: 1950 | B114: 110+ | C114: 0.81976 | D114: 1 | E114: 2026,01,22 | F114: 0 | G114: 0 | H114: 0 | I114: 0
A115: 1951 | B115: 0 | C115: 0.09608 | D115: 0.09002 | E115: 0.3 | F115: 100000 | G115: 9002 | H115: 93691 | I115: 6016098
A116: 1951 | B116: 1 | C116: 0.00835 | D116: 0.00832 | E116: 0.5 | F116: 90998 | G116: 757 | H116: 90619 | I116: 5922407
A117: 1951 | B117: 2 | C117: 0.00346 | D117: 0.00345 | E117: 0.5 | F117: 90241 | G117: 312 | H117: 90085 | I117: 5831787
A118: 1951 | B118: 3 | C118: 0.00209 | D118: 0.00209 | E118: 0.5 | F118: 89929 | G118: 188 | H118: 89835 | I118: 5741702
A119: 1951 | B119: 4 | C119: 0.00176 | D119: 0.00175 | E119: 0.5 | F119: 89742 | G119: 157 | H119: 89663 | I119: 5651867
A120: 1951 | B120: 5 | C120: 0.0014 | D120: 0.0014 | E120: 0.5 | F120: 89584 | G120: 125 | H120: 89522 | I120: 5562204
A121: 1951 | B121: 6 | C121: 0.00121 | D121: 0.00121 | E121: 0.5 | F121: 89459 | G121: 108 | H121: 89405 | I121: 5472682
A122: 1951 | B122: 7 | C122: 0.00115 | D122: 0.00115 | E122: 0.5 | F122: 89351 | G122: 102 | H122: 89300 | I122: 5383277
A123: 1951 | B123: 8 | C123: 0.001 | D123: 0.001 | E123: 0.5 | F123: 89248 | G123: 89 | H123: 89204 | I123: 5293978
A124: 1951 | B124: 9 | C124: 0.00095 | D124: 0.00095 | E124: 0.5 | F124: 89159 | G124: 85 | H124: 89117 | I124: 5204774
A125: 1951 | B125: 10 | C125: 0.00102 | D125: 0.00102 | E125: 0.5 | F125: 89075 | G125: 91 | H125: 89029 | I125: 5115657
A126: 1951 | B126: 11 | C126: 0.00093 | D126: 0.00093 | E126: 0.5 | F126: 88984 | G126: 82 | H126: 88942 | I126: 5026628
... A224: 1951 | B224: 109 | C224: 0.87629 | D224: 0.60932 | E224: 0.5 | F224: 0 | G224: 0 | H224: 0 | I224: 0
A225: 1951 | B225: 110+ | C225: 0.88964 | D225: 1 | E225: 2026,01,12 | F225: 0 | G225: 0 | H225: 0 | I225: 0
A226: 1952 | B226: 0 | C226: 0.08242 | D226: 0.07791 | E226: 0.3 | F226: 100000 | G226: 7791 | H226: 94523 | I226: 6164681
A227: 1952 | B227: 1 | C227: 0.0054 | D227: 0.00538 | E227: 0.5 | F227: 92209 | G227: 496 | H227: 91961 | I227: 6070157
A228: 1952 | B228: 2 | C228: 0.00202 | D228: 0.00202 | E228: 0.5 | F228: 91713 | G228: 185 | H228: 91620 | I228: 5978196
A229: 1952 | B229: 3 | C229: 0.00166 | D229: 0.00166 | E229: 0.5 | F229: 91527 | G229: 152 | H229: 91452 | I229: 5886576
A230: 1952 | B230: 4 | C230: 0.0012 | D230: 0.0012 | E230: 0.5 | F230: 91376 | G230: 110 | H230: 91321 | I230: 5795125
A231: 1952 | B231: 5 | C231: 0.00106 | D231: 0.00106 | E231: 0.5 | F231: 91266 | G231: 97 | H231: 91217 | I231: 5703804
A232: 1952 | B232: 6 | C232: 0.00083 | D232: 0.00083 | E232: 0.5 | F232: 91169 | G232: 75 | H232: 91131 | I232: 5612586
A233: 1952 | B233: 7 | C233: 0.00106 | D233: 0.00106 | E233: 0.5 | F233: 91094 | G233: 96 | H233: 91045 | I233: 5521455
A234: 1952 | B234: 8 | C234: 0.00097 | D234: 0.00097 | E234: 0.5 | F234: 90997 | G234: 88 | H234: 90953 | I234: 5430410
...
